Workbook
Name DQ.ADP_0_11_Months: DQs!$B$7:$E$25
Name DQ.ADP_24_71_Months: DQs!$F$7:$I$43
Name DQ.COG_0_23_Months: DQs!$AL$7:$AO$43
Name DQ.COG_24_71_Months: DQs!$AP$8:$AS$62
Name DQ.COM_0_23_Months: DQs!$T$7:$W$43
Name DQ.COM_24_71_Months: DQs!$X$7:$AA$43
Name DQ.MOT_0_23_Months: DQs!$AC$7:$AF$43
Name DQ.MOT_24_71_Months: DQs!$AG$8:$AJ$62
Name DQ.PS_0_23_Months: DQs!$K$7:$N$43
Name DQ.PS_24_71_Months: DQs!$O$7:$R$61

Sheet Summary
B1: Summary Profile
B3: Domain and Subdomain | C3: Age Equivalent (See Appendix A) | D3: Subdomain Raw Score Total | E3: Subdomain Percentile Rank | F3: Subdomain Scaled Score | H3: Sums of Subdomains and Scaled Scores
B4: Adaptive (ADP) | K4: Year | L4: Month | M4: Day
B5: Self-Care (SC) | C5: =IF(D5>0,LOOKUP(D5,'Age Equivalent'!B4:B66,'Age Equivalent'!C4:C66),"") -> 13 | D5: =SUM(SC!D6:D15,SC!D17:D19,SC!D21:D26,SC!H6:H11,SC!H13:H18,SC!H20:H27) -> 25 | E5: =IF(D5>0,LOOKUP('Scaled Scores'!D5,'Scaled Scores'!E5:E1104,'Scaled Scores'!G5:G1104),"") -> <1 | F5: =IF(D5>0,LOOKUP('Scaled Scores'!D5,'Scaled Scores'!E5:E1104,'Scaled Scores'!F5:F1104),"") -> 1 | G5: =IFERROR(LOOKUP(F5,'Other Metrics'!E2:E112,'Other Metrics'!F2:F112),"") -> -3 | J5: Date of Testing (mm/dd/yyyy) | L5: 46250
B6: Personal Responsibility (PR) | C6: =IF(L8<24,"",IF(D6>6,LOOKUP(D6,'Age Equivalent'!E4:E52,'Age Equivalent'!F4:F52),"<2")) -> 42 | D6: =IF(L8<24,"n/a",SUM(PR!D6:D9,PR!D11:D15,PR!D17:D19,PR!D21:D25,PR!H5,PR!H8:H18)) -> 16 | E6: =IF(L8<24,"",IF(D6>0,LOOKUP('Scaled Scores'!H5,'Scaled Scores'!I5:I682,'Scaled Scores'!K5:K682),"")) -> 75 | F6: =IF(L8<24,"",IF(D6>0,LOOKUP('Scaled Scores'!H5,'Scaled Scores'!I5:I682,'Scaled Scores'!J5:J682),"")) -> 12 | G6: =IF(L8<24,"",LOOKUP(F6,'Other Metrics'!E2:E112,'Other Metrics'!G2:G112)) -> 57 | J6: Date of Birth (mm/dd/yyyy) | L6: 45154
B7: Total | C7: =IF(SUM(C5:C6)>0,SUM(C5:C6),"") -> 55 | D7: =IF(SUM(D5:D6)>0,SUM(D5:D6),"") -> 41 | H7: =IFERROR(IF(SUM(F5:F6)>0,SUM(F5:F6),""),"") -> 13 | J7: Chronological Age | K7: =INT(DATEDIF(L6,L5,"y")) -> 3 | L7: =MOD(INT(DATEDIF(L6,L5,"m")),12) -> 0 | M7: =MOD(DATEDIF(L6,L5,"d"),365) -> 1
B8: Personal Social (P-S) | J8: Age in Months | L8: =DATEDIF(L6,L5,"M") -> 36
B9: Adult Interaction (AI) | C9: =IF(D9>0,LOOKUP(D9,'Age Equivalent'!H4:H60,'Age Equivalent'!I4:I60),"") -> 7 | D9: =SUM(AI!D6:D9,AI!D11:D18,AI!D20:D22,AI!D24:D27,AI!H6:H11,AI!H13:H15,AI!H17:H25) -> 16 | E9: =IF(D9>0,LOOKUP('Scaled Scores'!L5,'Scaled Scores'!M5:M1086,'Scaled Scores'!O5:O1086),"") -> <1 | F9: =IF(D9>0,LOOKUP('Scaled Scores'!L5,'Scaled Scores'!M5:M1086,'Scaled Scores'!N5:N1086),"") -> 1 | G9: =IFERROR(LOOKUP(F9,'Other Metrics'!E2:E112,'Other Metrics'!F2:F112),"") -> -3
B10: Peer Interaction (PI) | C10: =IF(L8<24,"",LOOKUP(D10,'Age Equivalent'!K4:K54,'Age Equivalent'!L4:L54)) -> 0 | D10: =IF(L8<24,"n/a",SUM(PI!D6:D7,PI!D9:D11,PI!D13:D15,PI!D21,PI!H6:H21)) -> 6 | E10: =IF(L8<24,"",IF(D10>0,LOOKUP('Scaled Scores'!P5,'Scaled Scores'!Q5:Q669,'Scaled Scores'!S5:S669),"")) -> <1 | F10: =IF(L8<24,"",IF(D10>0,LOOKUP('Scaled Scores'!P5,'Scaled Scores'!Q5:Q669,'Scaled Scores'!R5:R669),"")) -> 2 | G10: =IF(L8<24,"",LOOKUP(F10,'Other Metrics'!$E$2:$E$112,'Other Metrics'!$F$2:$F$112)) -> -3.67
B11: Self-Concept and Social Role (SR) | C11: =IF(D11>0,LOOKUP(D11,'Age Equivalent'!N4:N92,'Age Equivalent'!O4:O92),"") | D11: =SUM(SR!D6:D7,SR!D9:D10,SR!D12:D13,SR!D15:D24,SR!D26:D31,SR!D33:D35,SR!H5:H6,SR!H8:H13,SR!H15:H18,SR!H20:H33) -> 0 | E11: =IF(D11>0,LOOKUP('Scaled Scores'!T5,'Scaled Scores'!U5:U1113,'Scaled Scores'!W5:W1113),"") | F11: =IF(D11>0,LOOKUP('Scaled Scores'!T5,'Scaled Scores'!U5:U1113,'Scaled Scores'!V5:V1113),"") | G11: =IFERROR(LOOKUP(F11,'Other Metrics'!$E$2:$E$112,'Other Metrics'!$F$2:$F$112),"") | J11: Conversion Table for Sum of Sealed Scores
B12: Total | C12: =IF(SUM(C9:C11)>0,SUM(C9:C11),"") -> 7 | D12: =IF(SUM(D9:D11)>0,SUM(D9:D11),"") -> 22 | H12: =IFERROR(IF(SUM(F9:F11)>0,SUM(F9:F11),""),"") -> 3 | K12: Sum of Sealed Score | L12: Develop- mental Quotient | M12: Percentile Rank
B13: Communication (COM) | N13: Confidence Interval
B14: Receptive Communication (RC) | C14: =IF(D14>0,LOOKUP(D14,'Age Equivalent'!Q4:Q56,'Age Equivalent'!R4:R56),"") -> 3 | D14: =SUM('RC'!D6:D11,'RC'!D13:D19,'RC'!D21:D24,'RC'!D26:D38,'RC'!H6:H17,'RC'!H19:H26) -> 10 | E14: =IF(D14>0,LOOKUP('Scaled Scores'!X5,'Scaled Scores'!Y5:Y1120,'Scaled Scores'!AA5:AA1120),"") -> <1 | F14: =IF(D14>0,LOOKUP('Scaled Scores'!X5,'Scaled Scores'!Y5:Y1120,'Scaled Scores'!Z5:Z1120),"") -> 1 | G14: =IFERROR(LOOKUP(F14,'Other Metrics'!$E$2:$E$112,'Other Metrics'!$F$2:$F$112),"") -> -3
B15: Expressive Communication (EC) | C15: =IF(D15>0,LOOKUP(D15,'Age Equivalent'!T4:T69,'Age Equivalent'!U4:U69),"") -> 9 | D15: =SUM(EC!D6:D9,EC!D11:D17,EC!D19:D25,EC!D27:D40,EC!H6:H14,EC!H16:H35) -> 14 | E15: =IF(D15>0,LOOKUP('Scaled Scores'!AB5,'Scaled Scores'!AC5:AC1110,'Scaled Scores'!AE5:AE1110),"") -> <1 | F15: =IF(D15>0,LOOKUP('Scaled Scores'!AB5,'Scaled Scores'!AC5:AC1110,'Scaled Scores'!AD5:AD1110),"") -> 1 | G15: =IFERROR(LOOKUP(F15,'Other Metrics'!$E$2:$E$112,'Other Metrics'!$F$2:$F$112),"") -> -3 | J15: Adaptive (ADP) | K15: =IF(H7>0,H7,"") -> 13 | L15: =IFERROR(VLOOKUP($K$15,INDIRECT(DQs!$C$1),2,0),"") -> 84 | M15: =IFERROR(VLOOKUP($K$15,INDIRECT(DQs!$C$1),4,0),"") -> 14 | N15: =IFERROR(VLOOKUP($K$15,INDIRECT(DQs!$C$1),3,0),"") -> 77-93
B16: Total | C16: =IF(SUM(C14:C15)>0,SUM(C14:C15),"") -> 12 | D16: =IF(SUM(D14:D15)>0,SUM(D14:D15),"") -> 24 | H16: =IFERROR(IF(SUM(F14:F15)>0,SUM(F14:F15),""),"") -> 2 | J16: =B8 -> Personal Social (P-S) | K16: =+IF(SUM(F9:F11)>0,SUM(F9:F11),"") -> 3 | L16: =IFERROR(VLOOKUP($K$16,INDIRECT(DQs!$L$1),2,0),"") -> 55 | M16: =IFERROR(VLOOKUP($K$16,INDIRECT(DQs!$L$1),4,0),"") -> 0.1 | N16: =IFERROR(VLOOKUP($K$16,INDIRECT(DQs!$L$1),3,0),"") -> 51-61
B17: Motor (MOT) | J17: =B13 -> Communication (COM) | K17: =IF(H16>0,H16,"") -> 2 | L17: =IFERROR(VLOOKUP($K$17,INDIRECT(DQs!$U$1),2,0),"") -> 55 | M17: =IFERROR(VLOOKUP($K$17,INDIRECT(DQs!$U$1),4,0),"") -> 0.1 | N17: =IFERROR(VLOOKUP($K$17,INDIRECT(DQs!$U$1),3,0),"") -> 51-63
B18: Gross Motor (GM) | C18: =IF(D18>0,LOOKUP(D18,'Age Equivalent'!W4:W96,'Age Equivalent'!X4:X96),"") -> 9 | D18: =SUM(GM!D6:D13,GM!D15:D26,GM!D28:D35,GM!H6:H10,GM!H12:H15,GM!H17:H22,GM!H24:H27,GM!H29:H38) -> 30 | E18: =IF(D18>0,LOOKUP('Scaled Scores'!AF5,'Scaled Scores'!AG5:AG1118,'Scaled Scores'!AI5:AI1118),"") -> <1 | F18: =IF(D18>0,LOOKUP('Scaled Scores'!AF5,'Scaled Scores'!AG5:AG1118,'Scaled Scores'!AH5:AH1118),"") -> 1 | G18: =IFERROR(LOOKUP(F18,'Other Metrics'!$E$2:$E$112,'Other Metrics'!$F$2:$F$112),"") -> -3 | J18: =B17 -> Motor (MOT) | K18: =IF(H21>0,H21,"") -> 9 | L18: =IFERROR(VLOOKUP($K$18,INDIRECT(DQs!$AD$1),2,0),"") -> 62 | M18: =IFERROR(VLOOKUP($K$18,INDIRECT(DQs!$AD$1),4,0),"") -> 1 | N18: =IFERROR(VLOOKUP($K$18,INDIRECT(DQs!$AD$1),3,0),"") -> 57-73
B19: Fine Motor (FM) | C19: =IF(D19>0,LOOKUP(D19,'Age Equivalent'!Z4:Z64,'Age Equivalent'!AA4:AA64),"") -> 19 | D19: =SUM(FM!D6:D12,FM!D14:D18,FM!D20:D22,FM!D24:D25,FM!D27:D31,FM!H6:H12,FM!H14:H24) -> 28 | E19: =IF(D19>0,LOOKUP('Scaled Scores'!AJ5,'Scaled Scores'!AK5:AK1107,'Scaled Scores'!AM5:AM1107),"") -> 1 | F19: =IF(D19>0,LOOKUP('Scaled Scores'!AJ5,'Scaled Scores'!AK5:AK1107,'Scaled Scores'!AL5:AL1107),"") -> 3 | G19: =IFERROR(LOOKUP(F19,'Other Metrics'!$E$2:$E$112,'Other Metrics'!$F$2:$F$112),"") -> -2.33 | J19: =B22 -> Cognitive (COG) | K19: =IF(H26>0,H26,"") -> 11 | L19: =IFERROR(VLOOKUP($K$19,INDIRECT(DQs!$AM$1),2,0),"") -> 66 | M19: =IFERROR(VLOOKUP($K$19,INDIRECT(DQs!$AM$1),4,0),"") -> 1 | N19: =IFERROR(VLOOKUP($K$19,INDIRECT(DQs!$AM$1),3,0),"") -> 61-75
B20: Perceptive Motoe (PM) | C20: =IF(L8<24,"",IF(D20>0,LOOKUP(D20,'Age Equivalent'!AC4:AC34,'Age Equivalent'!AD4:AD34),"")) -> 0 | D20: =IF(L8<24,"n/a",SUM(PM!D6:D7,PM!D9:D10,PM!D12:D13,PM!D15:D17,PM!D19:D20,PM!H6:H8,PM!H10:H20)) -> 12 | E20: =IF(L8<24,"",IF(D20>0,LOOKUP('Scaled Scores'!AN5,'Scaled Scores'!AO5:AO688,'Scaled Scores'!AQ5:AQ688),"")) -> 5 | F20: =IF(L8<24,"",IF(D20>0,LOOKUP('Scaled Scores'!AN5,'Scaled Scores'!AO5:AO688,'Scaled Scores'!AQ5:AQ688),"")) -> 5 | G20: =IF(L8<24,"",LOOKUP(F20,'Other Metrics'!$E$2:$E$112,'Other Metrics'!$F$2:$F$112)) -> -1.67 | J20: =B28 -> DDI-2 Total | K20: =IF(SUM(K15:K19)>0,SUM(K15:K19),"") -> 38
B21: Total | C21: =IF(SUM(C18:C20)>0,SUM(C18:C20),"") -> 28 | D21: =IF(SUM(D18:D20)>0,SUM(D18:D20),"") -> 70 | H21: =IFERROR(IF(SUM(F18:F20)>0,SUM(F18:F20),""),"") -> 9
B22: Cognitive (COG)
B23: Attention and Memory (AM) | C23: =IF(D23>0,LOOKUP(D23,'Age Equivalent'!AF4:AF64,'Age Equivalent'!AG4:AG64),"") -> 16 | D23: =SUM(AM!D6:D10,AM!D12:D13,AM!D15:D17,AM!D19:D23,AM!D25:D26,AM!D28:D29,AM!D31:D43,AM!H6:H30) -> 28 | E23: =IF(D23>0,LOOKUP('Scaled Scores'!AR5,'Scaled Scores'!AS5:AS1100,'Scaled Scores'!AU5:AU1100),"") -> <1 | F23: =IF(D23>0,LOOKUP('Scaled Scores'!AR5,'Scaled Scores'!AS5:AS1100,'Scaled Scores'!AT5:AT1100),"") -> 2 | G23: =IFERROR(LOOKUP(F23,'Other Metrics'!$E$2:$E$112,'Other Metrics'!$F$2:$F$112),"") -> -3.67
B24: Reasoning and Academic Skills (RA) | C24: =IF(D24>0,LOOKUP(D24,'Age Equivalent'!AI4:AI40,'Age Equivalent'!AJ4:AJ40),"") -> 30 | D24: =SUM(RA!D6:D8,RA!D10:D16,RA!D18:D26,RA!H6:H26) -> 16 | E24: =IF(D24>0,LOOKUP('Scaled Scores'!AV5,'Scaled Scores'!AW5:AW688,'Scaled Scores'!AY5:AY688),"") -> 25 | F24: =IF(D24>0,LOOKUP('Scaled Scores'!AV5,'Scaled Scores'!AW5:AW688,'Scaled Scores'!AX5:AX688),"") -> 8 | G24: =IF(L8<24,"",LOOKUP(F24,'Other Metrics'!$E$2:$E$112,'Other Metrics'!$F$2:$F$112)) -> -0.67
B25: Perception and Concepts (PC) | C25: =IF(D25>0,LOOKUP(D25,'Age Equivalent'!AL4:AL52,'Age Equivalent'!AM4:AM52),"") -> 9 | D25: =SUM(PC!D6:D8,PC!D10:D11,PC!D13:D14,PC!D16:D25,PC!D27:D33,PC!H6:H20,PC!H22:H39) -> 10 | E25: =IF(D25>0,LOOKUP('Scaled Scores'!AZ5,'Scaled Scores'!BA5:BA1082,'Scaled Scores'!BC5:BC1082),"") -> <1 | F25: =IF(D25>0,LOOKUP('Scaled Scores'!AZ5,'Scaled Scores'!BA5:BA1082,'Scaled Scores'!BB5:BB1082),"") -> 1 | G25: =IFERROR(LOOKUP(F25,'Other Metrics'!$E$2:$E$112,'Other Metrics'!$F$2:$F$112),"") -> -3
B26: Total | C26: =IF(SUM(C23:C25)>0,SUM(C23:C25),"") -> 55 | D26: =IF(SUM(D23:D25)>0,SUM(D23:D25),"") -> 54 | H26: =IFERROR(IF(SUM(F23:F25)>0,SUM(F23:F25),""),"") -> 11
B28: DDI-2 Total

Sheet SC
B1: Adaptive (ADP)
B2: Self-Care (SC) | F2: Self-Care (SC)
B3: Item | C3: Item Description | D3: Score | F3: Item | G3: Item Description | H3: Score
D4: 0 1 2 | H4: 0 1 2
B5: 0-11 months | F5: 3 years
B6: SC-1 | C6: Sucks with smooth, coordinated movements | D6: 2 | F6: SC-17 | G6: Distinguishes between food and non-food substances
B7: SC-2 | C7: Places both hands on a bottle or breast during feeding | D7: 2 | F7: SC-18 | G7: Removes clothing unassisted
B8: SC-3 | C8: Mouths soft foods using up-and-down jaw movements and pushed food againts the top of their mouth with their tongue | D8: 2 | F8: SC-19 | G8: Accurately responds "yes" or "no" when asked if they need to use the toilet
F10: SC-20 | G10: Expresses a need to use the toilet
B11: SC-4 | C11: Takes strained food from a spoon and swallows it | D11: 2 | F11: SC-21 | G11: Controls bowel movements regularly
B12: SC-5 | C12: Eats semi-solid food when it is placed in their mouth | D12: 2 | F12: 4 years
B13: SC-6 | C13: Holds or supports a bottle to feed themselves | D13: 2 | F13: SC-22 | G13: Asks for food at the table
B14: SC-7 | C14: Uses their lips to remove food from an eating utensil | D14: 2 | F14: SC-23 | G14: Blows their nose with assistance
C15: held by an adult | D15: 2 | F15: SC-24 | G15: Washes and dries their hands with assistance
B16: 13-23 months | F16: SC-25 | G16: Obtains a drink from the tap without assistance
B17: SC-8 | C17: Feeds themselves bite-size pieces of food | D17: 2 | F17: SC-26 | G17: Chooses the appopriate utensil for the food they are eating
B18: SC-9 | C18: Drinks from a cup with assistance | D18: 2 | F18: SC-27 | G18: Sleeps throug the night without wetting the bed
B19: SC-10 | C19: Chews food using a rotary (side-to-side) jam movement | D19: 2 | F19: 5 years
B20: 2 years | F20: SC-28 | G20: Dresses and undresses without supervision
B21: SC-11 | C21: Helps dress themselves by holding out their arms/legs | D21: 2 | F21: SC-29 | G21: Takes care of their own toileting needs
B22: SC-12 | C22: Asks for food or liquid with words or gestures | D22: 1 | F22: SC-30 | G22: Puts on clothing and shoes correctly
B23: SC-13 | C23: Uses a spoon or other utiensil to feed themselves | F23: SC-31 | G23: Prepares a toothbrush and brushes their teeth
B24: SC-14 | C24: Removes their shoes without assistance | F24: SC-32 | G24: Cuts soft food with the side of a fork
B25: SC-15 | C25: Drinks from a cup without assitance with little spilling | F25: SC-33 | G25: Chooses clothing that is appropriate for the weather
B26: SC-16 | C26: Feeds themselves with a spoon or fork without assistance | F26: SC-34 | G26: Chooses clothing that is apporpriate for the occasion
F27: SC-35 | G27: Takes a bath or shower without assitance

Sheet PR
B1: Adaptive (ADP)
B2: Personal Responsibility (PR) | F2: Personal Responsibility (PR)
B3: Item | C3: Item Description | D3: Score | F3: Item | G3: Item Description | H3: Score
D4: 0 1 2 | H4: 0 1 2
B5: 2-3 years | F5: PR-14 | G5: Answers "what-to-do" questions You friend broke a leg _____ Pass _____ Fail You want to play longer _____ Pass _____ Fail
B6: PR-1 | C6: Moves independently around the house, requiring only occasional supervision | D6: 2
B8: PR-2 | C8: Understands that hot is dangerous | D8: 2 | F8: PR-15 | G8: Regularly performs 2 or more household chores
B9: PR-3 | C9: Puts away toys when asked | D9: 2 | F9: PR-16 | G9: Crosses the street safely
B10: 4 years | F10: PR-17 | G10: Knows their own phone number
B11: PR-4 | C11: Show care when handling an infant or small animal | D11: 2 | F11: PR-18 | G11: Goes to bed without assitance
B12: PR-5 | C12: Indicates or describes an illness to an adult | D12: 2 | F12: PR-19 | G12: Uses the telephone to place a call
B13: PR-6 | C13: Demonstrates caution and avoids common dangers | D13: 2 | F13: PR-20 | G13: Uses emergency phone numbers
B14: PR-7 | C14: Responds to instructions given in a small group and initiates an appropriate task without being reminded | D14: 2 | F14: PR-21 | G14: Knows their address
F15: PR-22 | G15: Makes a purchase in a store by themselves
B16: 5 years | F16: PR-23 | G16: Handles small sums of money responsibly
B17: PR-8 | C17: Uses appropriate behavior and voice in public settings | D17: 2 | F17: PR-24 | G17: Builds or repairs with appropriate tools or implements
B18: PR-9 | C18: Continues to work on a learning task with minimal guidance | F18: PR-25 | G18: Handles their own money
B19: PR-10 | C19: Initiates and organizes their own activities
B20: 6-7 years
B21: PR-11 | C21: Answers "what to do" questions involving responsibility
C22: Y N: You saw smoke and fire
C23: Y N: A stranger asked you to go on a ride
B24: PR-12 | C24: Follows rules when playing simple games
B25: PR-13 | C25: Asks permission to use others' possessions

Sheet AI
B1: Personal-Social (P-S)
B2: Adult Interaction (AI) | F2: Adult Interaction (AI)
B3: Item | C3: Item Description | D3: Score | F3: Item | G3: Item Description | H3: Score
D4: 0 1 2 | H4: 0 1 2
B5: 0-11 months | F5: 3 years
B6: AI-1 | C6: Looks at an adult's face | D6: 2 | F6: AI-15 | G6: Greets familiar adults spontaniously
B7: AI-2 | C7: Responds physically when held | D7: 2 | F7: AI-16 | G7: Enjoys having someone read simple stories to them
B8: AI-3 | C8: Shows awareness of other people | D8: 2 | F8: AI-17 | G8: Helps with simple household tasks
B9: AI-4 | C9: Shows a desire to picked up or held by familiar people | D9: 2 | F9: AI-18 | G9: Responds positively when familiar adults or adults in authority initiate social content
B10: 12-17 months
B11: AI-5 | C11: Explores adult facial features | D11: 2 | F11: AI-19 | G11: Allows others to participate in their activities
B12: AI-6 | C12: Shows a desire for social attention | D12: 2 | F12: 4 years
B13: AI-7 | C13: Expresses displeasure or dislike of certain activities or situation | D13: 2 | F13: AI-20 | G13: Initiates social contact or interactions with familiar adults
F14: AI-21 | G14: Seperates easily from the parent
B15: AI-8 | C15: Expresses enjoyment or preference of certain activities or situation | D15: 2 | F15: AI-22 | G15: Uses adults other than their parents as resources
F16: 5 years
B17: AI-9 | C17: Plays peek-a-boo | F17: AI-23 | G17: Asks for adult help when needed
B18: AI-10 | C18: Discriminates between familiar and unfamiliar people | F18: AI-24 | G18: Follows adult directions with little or no resisance
B19: 18-23 months | F19: AI-25 | G19: Follows the rules given by an adult for playing simple childhood games with peers
B20: AI-11 | C20: Shows appropriate signs of seperation anxiety when removed from their parent or caregive
F21: AI-26 | G21: Follows classroom rules and regulations
B22: AI-12 | C22: Continues to vocalize when imitated | F22: AI-27 | G22: Attempts to be humerous
B23: 2 years | F23: AI-28 | G23: Recognizes an adult's feelings
B24: AI-13 | C24: Shows appropriat levels of affection for people, pets or posessions | F24: AI-29 | G24: Trusts familiar adults and accepts explinations from them
F25: AI-30 | G25: Wait for their turn for adult's or teacher's attention
B26: AI-14 | C26: Responds positively to adult praise, rewards or promises of rewards

Sheet SR
B1: Personal-Social (P-S)
B2: Self Concept and Social Role (SR) | F2: Self Concept and Social Role (SR)
B3: Item | C3: Item Description | D3: Score | F3: Item | G3: Item Description | H3: Score
D4: 0 1 2 | H4: 0 1 2
B5: 0-11 months | F5: SR-25 | G5: Recognies the facial expressions of primary emotions
B6: SR-1 | C6: Smiles or vocalizes in response to adult attention | G6: P F : Happy P F : Sad
B7: SR-2 | C7: Enjoys frolic play | F7: 5 years
B8: 12-23 months | F8: SR-26 | G8: Is aware of differences between males and females
B9: SR-3 | C9: Expresses emotions | F9: SR-27 | G9: Recovers from distress in a reasonable amount of time when comforted
B10: SR-4 | C10: Shows awareness of their hands
B11: 2 years | F11: SR-28 | G11: Asserts themself in socialbly acceptable ways
B12: SR-5 | C12: Is aware of their feet | F12: SR-29 | G12: Recognizes another's need for help and offers assistance
B13: SR-6 | C13: Responds to their name | F13: SR-30 | G13: Shows a positive attitude towards school
B14: 2 1/2 years | F14: 6 years
B15: SR-7 | C15: Displays independent behavior | F15: SR-31 | G15: Describes their feelings
B16: SR-8 | C16: Identifies themselves in a mirror | F16: SR-32 | G16: Repondes properly ot the rights of others
B17: SR-9 | C17: Expresses ownership or posessions | F17: SR-33 | G17: Demonstrates the ability to "show-and-tell" without major discomfort.
B18: SR-10 | C18: Follows directions replated to their daily routine
B19: SR-11 | C19: Appropriately communicaes a range of positive emotions | F19: 7 years
B20: SR-12 | C20: Imitates others and changes their behavior based on what they are doing | F20: SR-34 | G20: Recognizes the feelings of others
F21: SR-35 | G21: Uses adults appropriately to help resolve peer conflict
B22: SR-13 | C22: Shows pride in accomplishments | F22: SR-36 | G22: Discriminates between socially acceptable and unacceptable bevavior
B23: SR-14 | C23: Expresses enthusiasm for work or play
B24: SR-15 | C24: Appropriately communicaes a range of negative emotions | F24: SR-37 | G24: Shoes moral responsibility
B25: 3 years | F25: SR-38 | G25: Delays gratification until a task is complete
B26: SR-16 | C26: States their first name | F26: SR-39 | G26: Copes with criticism and teasing.
B27: SR-17 | C27: Uses object in make-believe play | F27: SR-40 | G27: Admits responsibility for error or wrongdoing
B28: SR-18 | C28: Uses words for social contact | F28: SR-41 | G28: Considers the emotioal or connitive perspecitve of others
B29: SR-19 | C29: Uses a personal pronoun to refer to themselvf | F29: SR-42 | G29: Sees alternatives to problems with adult assistance
B30: SR-20 | C30: States their age | F30: SR-43 | G30: Stays on task and works through difficulties and frustrations
B31: SR-21 | C31: Engages in adult role-playing and imitation | F31: SR-44 | G31: Copes independantly and appropriately with peer aggression directed towards them.
B32: 4 years
B33: SR-22 | C33: States whether they are male or female | F33: SR-45 | G33: Describes their personality
B34: SR-23 | C34: States their first and last name
B35: SR-24 | C35: Speaks positively about themselves

Sheet RC
B1: Communication (COM)
B2: Receptive Communication (RC) | F2: Receptive Communication (RC)
B3: Item | C3: Item Description | D3: Score | F3: Item | G3: Item Description | H3: Score
D4: 0 1 2 | H4: 0 1 2
B5: 0-11 months | F5: 4 years
B6: RC-1 | C6: Responds to a non-speech shound outside their field of vision | D6: 2 | F6: RC-18 | G6: Follows 2-step verbal command
F7: RC-19 | G7: Responds to the prepositions "toward" and "behind" Toward Pass Fail Behind Pass Fail
B8: RC-2 | C8: Responds to a voice outsied their field of vision | D8: 2
B9: RC-3 | C9: Is soothed by a familiar adult's voice | D9: 2
B10: RC-4 | C10: Thruns their head toward the source of a sound outside their field of vision | D10: 2 | F10: RC-20 | G10: Respnds to the adverbs "softly" and "loudly"
F11: RC-21 | G11: Understand regular plural forms Boy with the cats Pass Fail Boy in the batchtub Pass Fail
B12: 12-23 months
B13: RC-5 | C13: Attends to someone speasking to them for at least 10 seconds | D13: 2
B14: RC-6 | C14: Responds with awareness, acceptance and in a socially appropriate ways when a familiar person approaches, touches or talks to them | F14: RC-22 | G14: Undersands the superatives "biggest" and "longest"
F15: RC-23 | G15: Responds to "where" and "when" questions Where Pass Fail When Pass Fail
B17: RC-7 | C17: Responds to different tones of a person's voice
B18: RC-8 | C18: Attends to other people's conversations for 30 seconds | F18: 5-6 years
B19: RC-9 | C19: Associates spoken words with familiar objects or actions | F19: RC-24 | G19: Understands simple negations
B20: 2 years | F20: RC-25 | G20: Associated spoken words with pictures Bird Pass Fail Hen Pass Fail Telephone: Pass Fail
B21: RC-10 | C21: Identifies family members or pets when named
B22: RC-11 | C22: Responds to simultaneous verbal and gestural commands
B23: RC-12 | C23: Looks at or points to an object across the room when it is named. | F23: RC-26 | G23: Recalls events from a story presented orally -- Level 1 Ball Pass Fail Tippy (dog) Pass Fail Sat down Pass Fail
B25: 3 years
B26: RC-13 | C26: Follows 3 or more verbal command
B27: RC-14 | C27: Responds to the prepositions "out" and "on" Out Pass Fail On Pass Fail
B30: RC-15 | C30: Understands the simple possessive forms "your" and "my" Your foot Pass Fail My foot Pass Fail
B33: RC-16 | C33: Responds to "who" and "what" quesrtions Who Pass Fail What Pass Fail
B36: RC-17 | C36: Understands the simple posessive form 's Baby's mouth Pass Fail Daddy's boy Pass Fail

Sheet EC
B1: Communication (COM)
B2: Expressive Communication (EC) | F2: Expressive Communication (EC)
B3: Item | C3: Item Description | D3: Score | F3: Item | G3: Item Description | H3: Score
D4: 0 1 2 | H4: 0 1 2
B5: 0-11 months | F5: 4 years
B6: EC-1 | C6: Produces differential cries | D6: 2 | F6: EC-22 | G6: Asks questions that begin with "who" and "where"
B7: EC-2 | C7: Produces one or more vowel sounds | D7: 2 | F7: EC-23 | G7: Names their creation and labels its elements
B8: EC-3 | C8: Babbles | D8: 2 | F8: EC-24 | G8: Asks questions that begin with "why" and "how"
B9: EC-4 | C9: Vocalizesto express their feelings | D9: 2 | F9: EC-25 | G9: Uses the articles "the" and "a" I see a cow Pass Fail I read the book Pass Fail The bike is red Pass Fail I am drawing a dog Pass Fail
B10: 12-23-months
B11: EC-5 | C11: Produces one or more single-sylable consonant-vowel sounds | D11: 2
B13: EC-6 | C13: Repeats one or more single-sylable consonant-vowel sounds in close succession | D13: 2
F14: EC-26 | G14: Uses 5- or 6-word sentances
B15: EC-7 | C15: Waves "bye-bye" | D15: 2 | F15: 5 years
B16: EC-8 | C16: Initiates speech sounds | F16: EC-27 | G16: Uses plural forms ending with "s" or "z" sound Cups Pass Fail Dolls Pass Fail Trucks Pass Fail Spoons Pass Fail
B17: EC-9 | C17: Uses gestures to indicate wants or needs
B18: 2 years
B19: EC-10 | C19: Uses variations in their voice
B20: EC-11 | C20: Spontaneously initiates sounds words, or gestures that are associated with objects in the immediate environment
F21: EC-28 | G21: Communicated their experiences clearly enough for others to understand
B22: EC-12 | C22: Uses 10 or more words
B23: EC-13 | C23: Communicates in a back-and-forth, turn-taking style using sounds, gestures, or other nonverbal methods | F23: EC-29 | G23: Repeats familiar words with clear articulation Cup C P House H S Window W D Match M CH Rabbit R B Begun B N Bake B K Ring NG Jump J Plant PL Draw DR Shove SH V
B25: EC-14 | C25: Uses 2-word utterances to express meaniful relationships
B26: 3 years
B27: EC-15 | C27: Uses words to express what they see and do and to express the experiences that immediately affect them
B29: EC-16 | C29: Uses words to get their needs meet
B30: EC-17 | C30: Uses 3-word phrases meaningfully
B31: EC-18 | C31: Engages in extended and meaningful nonverbal exchanges with others
B33: EC-19 | C33: Uses the pronouns "I", "you", and "me"
B34: EC-20 | C34: Uses words to relate information about other people, their actions, or their experiences
B36: EC-21 | C36: Responds "yes" or "no" appropriately Shoes On? Pass Fail Standing on a table? Pass Fail Sitting in a chair Pass Fail Elephant in the room? Pass Fail

Sheet PI
B1: Personal-Social (P-S)
B2: Peer Interaction | F2: Peer Interaction
B3: Item | C3: Item Description | D3: Score | F3: Item | G3: Item Description | H3: Score
D4: 0 1 2 | H4: 0 1 2
B5: 2 years | F5: 5 years
B6: PI-1 | C6: Shows awareness of the presence of other children | D6: 2 | F6: PI-13 | G6: Initiates social contacts and interactions with peers
B7: PI-2 | C7: Enjoys playing with other children | D7: 2 | F7: PI-14 | G7: Has special friends
B8: 2 1/2 years | F8: PI-15 | G8: Willingly talks turns and shares
B9: PI-3 | C9: Plays independently in the company of peers | D9: 2 | F9: PI-16 | G9: Cooperated in group activities
B10: PI-4 | C10: Initiates social contact with peers in play | F10: PI-17 | G10: Willingly participates in new or unexpected activities or tasks
B11: PI-5 | C11: Imitates the play activity of other children
B12: 3 years | F12: PI-18 | G12: Uses peers as resources
B13: PI-6 | C13: Responds differently to familiar and unfamiliar children | F13: PI-19 | G13: Exchanges ideas with other children and goes along with other children's ideas
B14: PI-7 | C14: Plays with a peer, using the samematerials, without disturbing the other child's play
F15: PI-20 | G15: Participates in competitive play activities
B16: 4 years | F16: PI-21 | G16: Resolves a conflict with a peer without using aggression or violence
B17: PI-8 | C17: Expresses affection or liking of a peer
B18: PI-9 | C18: Shows sympath or concern for others | F18: PI-22 | G18: Assumes a leadershio role in peer relationships
B19: PI-10 | C19: Interacts appropriatly with peers in nonplay group activities | F19: PI-23 | G19: Initiates prosocial interactions
B20: PI-11 | C20: Shares properly with others | F20: PI-24 | G20: Recognizes the basic similarities of all children
B21: PI-12 | C21: Play cooperatively with peers | F21: PI-25 | G21: Recognizes and accepts diversity among other children

Sheet GM
B1: Motor (MOT)
B2: Gross Motor (GM) | F2: Gross Motor (GM)
B3: Item | C3: Item Description | D3: Score | F3: Item | G3: Item Description | H3: Score
D4: 0 1 2 | H4: 0 1 2
B5: 0-5 months | G5: 18-23 months
B6: GM-1 | C6: Maintains an upright posture at an adult's shoulder without assitance for at leat 2 minutes | D6: 2 | F6: GM-20 | G6: Creeps or crawls up to 4 steps without assistance
F7: GM-21 | G7: Walks without support for 10 feet without falling
B8: GM-2 | C8: Holds their head erect for 1 minute when help | D8: 2 | F8: GM-22 | G8: Moves from a sitting to standing position without support
B9: GM-3 | C9: Lifts their head and holds it up for 5 seconds while lying in a prone position | D9: 2 | F9: GM-23 | G9: Moves from a pupine to standing position using smooth, coordinated movement without support or assitance
B11: GM-4 | C11: Lifts and turns their head from side to side while lying in a prone position | D11: 2 | F11: 2 years
F12: GM-24 | G12: Maintains or corrects their balance when moving from a standing positionother nonvertical positions
B13: GM-5 | C13: Brings their hands together at the midline | D13: 2
B14: 6-11 months | F14: GM-25 | G14: Walks up 4 stairs without support
B15: GM-6 | C15: Turns their head freely from side-to-side while supported in a sitting position | D15: 2 | F15: GM-26 | G15: Walks down 4 steps without support
F16: 3 years
B17: GM-7 | C17: Holds their head parallel to the body when pulled from a surpine to a seated position | D17: 2 | F17: GM-27 | G17: Runs 10 feet without falling
F18: GM-28 | G18: Kicks a ball forward without falling
B19: GM-8 | C19: Moves their arms when a toy is in sight | D19: 2 | F19: GM-29 | G19: Walks up and down stairs without assitance
B20: GM-9 | C20: Puts objects into their mouth | D20: 2 | F20: GM-30 | G20: Walks backwards 5 feet
B21: GM-10 | C21: Moves an object from hand to mounth | D21: 2 | F21: GM-31 | G21: Throws a ball 5 feet forward with direction
B22: GM-11 | C22: Turns from a prone to a supine position unassisted | D22: 2 | F22: GM-32 | G22: Jumps forward with both fet together
B23: GM-12 | C23: Intentionally secures a nearby object while in a prone position | D23: 2 | F23: 4 years
F24: GM-33 | G24: Walks forward 2 or more steps on a line on the floor, apternating feet
B25: GM-13 | C25: Sits without assitance for at leat 5 seconds | D25: 2
B26: GM-14 | C26: Makes stepping movements when held in an upright position | D26: 2 | F26: GM-34 | G26: Walks down stairs without assistance alternating feet
B27: 12-17 months | F27: GM-35 | G27: Imitates the bilateral movements of an adult
B28: GM-15 | C28: Moves 3 or more feet by crawling | D28: 2 | F28: 5 years
B29: GM-16 | C29: Puts themselves in a standing position while holding on to a solid object without adult assistance | F29: GM-36 | G29: Bends over and touches the floor with both hands
F30: GM-37 | G30: Catches an 8-inch ball from 5 feet away with both hands
B31: GM-17 | C31: Moves from a standing to sitting position while holding a solid object | F31: GM-38 | G31: Walks in a straight line, heel-to-toe, for 4 or more steps
F32: GM-39 | G32: Hops forward on one foot without support
B33: GM-18 | C33: Walks for 3 or more steps without assitance | F33: GM-40 | G33: Stands on each foot alternately with eyes closed
B34: GM-19 | C34: Stands in an upreight position without support for 30 or more seconds. | F34: GM-41 | G34: Walks a 6-foot line on the floor, heel-to-toe, with eyes open
F35: GM-42 | G35: Skips on alrernate feet for 20 feet
F36: GM-43 | G36: Throws a ball and hits target with dominant hand
F37: GM-44 | G37: Jumps rope without assistance
F38: GM-45 | G38: Throws a ball and hits target with non-dominant hand

Sheet FM
B1: Motor (MOT)
B2: Fine Motor (FM) | F2: Fine Motor (FM)
B3: Item | C3: Item Description | D3: Score | F3: Item | G3: Item Description | H3: Score
D4: 0 1 2 | H4: 0 1 2
C5: 0-11 months | G5: 4 years
B6: FM-1 | C6: Holds hands in a open, loose-fisted position when not grasping an object | D6: 2 | F6: FM-17 | G6: Strings 4 large beads
F7: FM-18 | G7: Holds paper with one hand while drawing or writing with the other hand
B8: FM-2 | C8: Holds their hands together at the midline | D8: 2
B9: FM-3 | C9: Holds an object with their fingers against the heel of the palm (ulnar-palmar prehension) | D9: 2 | F9: FM-19 | G9: Fastens clothing without assitance
F10: FM-20 | G10: Wiggle their thumb in bending, circularm and back-and-forth movements
B11: FM-4 | C11: Holds an object for 1 minute | D11: 2
B12: FM-5 | C12: Holds hands in an open position when not grasping an object | D12: 2 | F12: FM-21 | G12: Traces designs with curved edges
B13: 12-17 months | F13: 5 years
B14: FM-6 | C14: Retrieves a small object by raking it with their fingers and pulling it to the palm of the hand | D14: 2 | F14: FM-22 | G14: Traces designs with corners
F15: FM-23 | G15: Folds a sheet of paper
B16: FM-7 | C16: Transfers and object from one hand ot the other | D16: 2 | F16: FM-24 | G16: Folds a piece of paper twice -- one horizontally and again vertically at right angles.
B17: FM-8 | C17: Picks up a rasin with several fingers opposed to the thumb (partial finger prehension) | D17: 2
F18: FM-25 | G18: Opens a smapp padlock with a key
B19: 18-23 months | F19: FM-26 | G19: Cuts with sissors following a line
B20: FM-9 | C20: Drops an object intentionally with demonstration | D20: 2 | F20: FM-27 | G20: Crumples pieces of paper into balls with each hand
B21: FM-10 | C21: Picks up a rasin with the ends of the thumb and index finger in an overhand approach (neat pincer grasp) | D21: 2 | F21: FM-28 | G21: Touches the fingertips of each hand successlvey with the thumb of the same hand
B23: 2 years | F23: FM-29 | G23: Ties a single overhand knot around a cryon with a string
B24: FM-11 | C24: Extrends a toy to a person and releases it from their grasp | D24: 2 | F24: FM-30 | G24: Catches a tennis ball, tossed from 6 feet, with on hand
B25: FM-12 | C25: Intentionally propels or throws an object | D25: 2
B26: 3 years
B27: FM-13 | C27: Removes forms from a form board | D27: 2
B28: FM-14 | C28: Extends or points with their index finger independent of the thumb and other fingers | D28: 2
B30: FM-15 | C30: Scribbles linear and/or circular patterns spontaneously
B31: FM-16 | C31: Uses pads of fingertips to grasp pencil

Sheet PM
B1: Motor (MOT)
B2: Perceptial Motor (PM) | F2: Perceptial Motor (PM)
B3: Item | C3: Item Description | D3: Score | F3: Item | G3: Item Description | H3: Score
D4: 0 1 2 | H4: 0 1 2
C5: 2 years | G5: 6 years
B6: PM-1 | C6: Reaches for and touches an object placed in front to them | F6: PM-12 | G6: Copies a cross
B7: PM-2 | C7: Reaches for an object with one hand | D7: 2 | F7: PM-13 | G7: Copies the letters "V","H", and "T"
B8: 2 1/2 years | F8: PM-14 | G8: Draws a person with 6 parts
B9: PM-3 | C9: Intentionall drops a cube into a cup with demonstration | D9: 2 | F9: 7 years
B10: PM-4 | C10: Places a rasin in a bottle | D10: 2 | F10: PM-15 | G10: Copies the numerals "1" though "5"
C11: 3 years | F11: PM-16 | G11: Copies simple words
B12: PM-5 | C12: Dumps a rasin from a bottle | D12: 2 | F12: PM-17 | G12: Copies a triangle
B13: PM-6 | C13: Place 4 rings on a post in any order | D13: 2 | F13: PM-18 | G13: Copies words with uppercase and lowercase letters
B14: 4 yeats | F14: PM-19 | G14: Copies directional arrows
B15: PM-7 | C15: Stacks 2 cubes | D15: 2 | F15: PM-20 | G15: Copies a diamond
B16: PM-8 | C16: Imitates circular markings | F16: PM-21 | G16: Copies 2 tilted triangles
B17: PM-9 | C17: Stakcs 8 cubes vertically | F17: PM-22 | G17: Copies a 2-dimentional design
B18: 5 years | F18: PM-23 | G18: Copies a 3-dimentional clinder design
B19: PM-10 | C19: Imitates veritcla and horizontal markings | F19: PM-24 | G19: Copies a 3-dimentional box design
B20: PM-11 | C20: Copies a circle | F20: PM-25 | G20: Writes in script (cursive) rather than printing

Sheet AM
B1: COGNITIVE (COG)
B2: Attention and Memory (AM) | F2: Attention and Memory (AM)
B3: Item | C3: Item Description | D3: Score | F3: Item | G3: Item Description | H3: Score
D4: 0 1 2 | H4: 0 1 2
C5: 0-5 months | F5: 5 years
B6: AM-1 | C6: Visually attends to a light source moving in a 180-degree arc | D6: 2 | F6: AM-21 | G6: Focuses their attention on one task while being aware of, but not distracted by, surrounding activities
B7: AM-2 | C7: Turns their eyes toward a light source | D7: 2
B8: AM-3 | C8: Visually attends to a light source moving in a vertical direction | D8: 2 | F8: AM-23 | G8: Recalls familiar objects Shoe ____ Pass ____ Fail Cube ____ Pass ____ Fail
B10: AM-4 | C10: Shows anticipatory excitement | D10: 2
B11: 6-11 months | F11: AM-24 | G11: Located hidden items in a picture scene: Time _____ Min _____ Sec Items found after 2 minutes _____ Ball _____ Glue Bottle _____ Eraser _____ Red Crayon _____ Unicord _____ Compass
B12: AM-5 | C12: Visually attends to an object for 5 or more seconds | D12: 2
B13: AM-6 | C13: Follows a auditory stimulus | D13: 2
B14: 12-17 months
B15: AM-7 | C15: Follows a verticle stimulus | D15: 2
B16: AM-8 | C16: Attends to an obgoing sound or activity for 15 or more seconds | D16: 2
F17: AM-25 | G17: Says alphabet by rote
B18: 18-23 months | F18: AM-26 | G18: Repeats 4-digit sequences 3, 1, 4, 8 _____ Pass _____ Fail 9, 6, 8, 2 _____ Pass _____ Fail
B19: AM-9 | C19: Occupies themselves for 5 minutes | D19: 2
B20: AM-10 | C20: Attends to a game of peekaboo for 1 minute | D20: 2
B21: AM-11 | C21: Uncovers a hidden toy | D21: 2 | F21: AM-27 | G21: Recalls facts form an oral story Where was the dog running? ____ Pass ____ Fail What color was the dog? ____ Pass ____ Fail What did the dog do when the cat was in the tree? ____ Pass ____Fail
B22: AM-12 | C22: Occupies themselves for 10 or more minutes without demanding attention | D22: 2
B24: 2 years
B25: AM-13 | C25: Searches for a removed object | D25: 2
B26: AM-14 | C26: Looks at, points to, or touches pictures in a book | D26: 2 | F26: AM-28 | G26: Repeats sequences of 4 and 5 objects from memory
B27: 3 years | F27: AM-29 | G27: Repeats sequences of 6 and 7 objects from memory
B28: AM-15 | C28: Attends to one activity for 3 or more minutes | F28: AM-30 | G28: Repeats 6-digit sequences 8, 9, 1, 7, 4, 3 ____ Pass ____ Fail 7, 2, 6, 4, 8, 3 ____ Pass ____ Fail
B29: AM-16 | C29: Finds an object hidden under one of two cups
B30: 4 years
B31: AM-17 | C31: Selects the hand hiding a toy
B32: AM-18 | C32: Attends to a learning task or story in a small group for 5 min
B33: AM-19 | C33: Recites memorized lines from books, poems, television shows or songs.
B35: AM-20 | C35: Located hidden items in a picture scene Time: ______ min. ______ sec. Items found within 3 minutes: ____ Beach Ball ____ Frog ____ Butterfly ____ Ice cream cone ____ Bird ____ Squirrel

Sheet RA
B1: COGNITIVE (COG)
B2: Attention and Memory (AM) | F2: Attention and Memory (AM)
B3: Item | C3: Item Description | D3: Score | F3: Item | G3: Item Description | H3: Score
D4: 0 1 2 | H4: 0 1 2
C5: 2 years | G5: 5 years
B6: RA-1 | C6: Recognizes themselves as the cause of events or happenings | D6: 2 | F6: RA-11 | G6: Give three objects on request
B7: RA-2 | C7: Experiments with variations of causal behavior | D7: 2 | F7: RA-12 | G7: Finds comical, unexpected, or unusal events humrous
B8: RA-3 | C8: Reaches around a barrier to obtain a toy | D8: 2 | F8: RA-13 | G8: Identifies the larget of two nubers: 5 pennies _____ Pass _____ Fail 8 _____ Pass _____ Fail
C9: 3 years
B10: RA-4 | C10: Show interest and enjoyment in age-appropriate books or printed materials | D10: 2
F11: RA-14 | G11: Completes learning tasks having 2 or more steps without assistance
B12: RA-5 | C12: Pulls a cloth to obtain an object | D12: 2
B13: RA-6 | C13: Nests objects inside each other | D13: 2 | F13: RA-15 | G13: Answers simple logic questions Why to we have clothes? _____ Pass _____ Fail Why to people have cars? _____ Pass _____ Fail
B14: RA-7 | C14: Matches colors: Red ____ Pass ____ Fail Green ____ Pass ____ Fail Blue ____ Pass ____Fail Yellow ____ Pass ____ Fail | D14: 2
F16: RA-16 | G16: Recognizes picture absurdities Picture A _____ Pass _____ Fail Picture B _____ Pass _____ Fail
B17: 4 years
B18: RA-8 | C18: Responds to "one" and "one more" | D18: 2
B19: RA-9 | C19: Names the colors "red", "green", and "blue": Red _____ Pass _____ Fail Green _____ Pass _____ Fail Blue _____ Pass _____ Fail | F19: RA-17 | G19: Complete opposite analogies Sister is a girl; brother is a _______ _____ Pass _____ Fail Fire is hot; Ice is _______ _____ Pass ____ Fail In the daytime it is light; at night it is _____ Pass ____ Fail
B23: RA-10 | C23: Identifies sources of common actions: What flies? _____ Pass _____ Fail What barks? _____ Pass _____ Fail What sleeps? _____ Pass _____ Fail | F23: RA-18 | G23: Identifies the missing parts of objects Wheel _____ Pass _____ Fail Eye _____ Pass _____ Fail Thumb _____ Pass _____ Fail

Sheet PC
B1: COGNITIVE (COG)
B2: Perception and Concpts (PC) | F2: Perception and Concpts (PC)
B3: Item | C3: Item Description | D3: Score | F3: Item | G3: Item Description | H3: Score
D4: 0 1 2 | H4: 0 1 2
C5: 0-11 months | G5: 4 years (continued)
B6: PC-1 | C6: Responds positively to physical contact and tactile stimulation | D6: 2 | F6: PC-15 | G6: Identifies colors of familiar objects not in view Orange _____ Pass _____ Fail Green or Yellow _____ Pass _____ Fail
B8: PC-2 | C8: Visually explores the environment | D8: 2
B9: 12-23 months | F9: PC-16 | G9: Recognizes visual differences among similar shapes Set A _____ Pass _____ Fail Set B _____ Pass _____ Fail Set C _____ Pass _____ Fail
B10: PC-3 | C10: Shows awareness of new situations | D10: 2
B11: PC-4 | C11: Feels and explores objects | D11: 2
B12: 2 years
B13: PC-5 | C13: Physically explores or investigates their surroundings | D13: 2 | F13: PC-17 | G13: Identifies simple objects by touch Bead _____ Pass _____ Fail Square _____ Pass _____ Fail
B14: PC-6 | C14: Imitates simple factial gestures
B15: 3 years
B16: PC-7 | C16: Places a circle and a square in a foam board | F16: PC-18 | G16: Recognizes visual differences among similar numerals and letters Set A _____ Pass _____ Fail Set B _____ Pass _____ Fail Set C _____ Pass _____ Fail
B17: PC-8 | C17: Matches a circle, square, and triangle Circle _____ Pass _____ Fail Square _____ Pass _____ Fail Triangle _____ Pass _____ Fail
B21: PC-9 | C21: Identifies familiar objects by their use Shoe _____ Pass _____ Fail Cup _____ Pass _____ Fail Ball _____ Pass _____ Fail | F21: 5 years
F22: PC-19 | G22: Identifies soft, rough, and smooth textures Soft _____ Pass _____ Fail Rough _____ Pass _____ Fail Smooth _____ Pass _____ Fail
B25: PC-10 | C25: Sorts by color with demonstration
B26: 4 years | F26: PC-20 | G26: Compares the sizes of familir objects not in view Dog _____ Pass _____ Fail Tree _____ Pass _____ Fail Room _____ Pass _____ Fail
B27: PC-11 | C27: Identifies big and little shapes
B28: PC-12 | C28: Sorts by size with demonstration
B29: PC-13 | C29: Sorts forms by shapes Squares _____ Pass _____ Fail Circles _____ Pass _____ Fail Rectangles _____ Pass _____ Fail
F30: PC-21 | G30: assemples a 6-piece puzzle of a person
F31: PC-22 | G31: Identiifes the picture that is different -- Level 1 Tree _____ Pass _____ Fail Dog _____ Pass _____ Fail
B33: PC-14 | C33: Identifies the longer of 2 plastic strips
F34: PC-23 | G34: Understands relative time Every year _____ Pass _____ Fail Minutes _____ Pass _____ Fail Every Week _____ Pass _____ Fail One Week _____ Pass _____ Faile
F39: PC-24 | G39: Identifies past and present activites

Sheet Age Equivalent
B2: ADP - SC | E2: ADP - PR | H2: P-S - AI | K2: P-S - PI | N2: P-S - SR | Q2: COM - RC | T2: COM-EC | W2: MOT - GM | Z2: MOT - FM | AC2: MOT - PM | AF2: COG - AM | AI2: COM - RA | AL2: COG - PC
B3: Score | C3: Age Eq | E3: Score | F3: Age Eq | H3: Score | I3: Age Eq | K3: Score | L3: Age Eq | N3: Score | O3: Age Eq. | Q3: Score | R3: Eq Age | T3: Score | U3: Eq Age | W3: Score | X3: Eq Age | Z3: Score | AA3: Eq Age | AC3: Score | AD3: Eq Age | AF3: Score | AG3: Eq Age | AI3: Score | AJ3: Eq Age | AL3: Score | AM3: Eq Age
B4: 3 | C4: 0 | E4: 6 | F4: 24 | H4: 4 | I4: 0 | K4: 0 | L4: 0 | N4: 0 | O4: 0 | Q4: 0 | R4: 0 | T4: 0 | U4: 0 | W4: 0 | X4: 0 | Z4: 0 | AA4: 0 | AC4: 0 | AD4: 0 | AF4: 0 | AG4: 0 | AI4: 0 | AJ4: 0 | AL4: 0 | AM4: 0
B5: =B4+1 -> 4 | C5: 1 | E5: =E4+1 -> 7 | F5: 24 | H5: 5 | I5: 0 | K5: =K4+1 -> 1 | L5: 0 | N5: =N4+1 -> 1 | O5: 0 | Q5: =Q4+1 -> 1 | R5: 0 | T5: =T4+1 -> 1 | U5: 0 | W5: =W4+1 -> 1 | X5: 0 | Z5: =Z4+1 -> 1 | AA5: 0 | AC5: =AC4+1 -> 1 | AD5: 0 | AF5: =AF4+1 -> 1 | AG5: 0 | AI5: =AI4+1 -> 1 | AJ5: 0 | AL5: =AL4+1 -> 1 | AM5: 0
B6: =B5+1 -> 5 | C6: 3 | E6: =E5+1 -> 8 | F6: 25 | H6: 6 | I6: 1 | K6: =K5+1 -> 2 | L6: 0 | N6: =N5+1 -> 2 | O6: 0 | Q6: =Q5+1 -> 2 | R6: 0 | T6: =T5+1 -> 2 | U6: 0 | W6: =W5+1 -> 2 | X6: 0 | Z6: =Z5+1 -> 2 | AA6: 0 | AC6: =AC5+1 -> 2 | AD6: 0 | AF6: =AF5+1 -> 2 | AG6: 0 | AI6: =AI5+1 -> 2 | AJ6: 0 | AL6: =AL5+1 -> 2 | AM6: 0
B7: =B6+1 -> 6 | C7: 4 | E7: =E6+1 -> 9 | F7: 28 | H7: 7 | I7: 2 | K7: =K6+1 -> 3 | L7: 0 | N7: =N6+1 -> 3 | O7: 1 | Q7: =Q6+1 -> 3 | R7: 0 | T7: =T6+1 -> 3 | U7: 0 | W7: =W6+1 -> 3 | X7: 0 | Z7: =Z6+1 -> 3 | AA7: 0 | AC7: =AC6+1 -> 3 | AD7: 0 | AF7: =AF6+1 -> 3 | AG7: 0 | AI7: =AI6+1 -> 3 | AJ7: 0 | AL7: =AL6+1 -> 3 | AM7: 0
B8: =B7+1 -> 7 | C8: 5 | E8: =E7+1 -> 10 | F8: 31 | H8: 8 | I8: 2 | K8: =K7+1 -> 4 | L8: 0 | N8: =N7+1 -> 4 | O8: 1 | Q8: =Q7+1 -> 4 | R8: 0 | T8: =T7+1 -> 4 | U8: 0 | W8: =W7+1 -> 4 | X8: 0 | Z8: =Z7+1 -> 4 | AA8: 0 | AC8: =AC7+1 -> 4 | AD8: 0 | AF8: =AF7+1 -> 4 | AG8: 0 | AI8: =AI7+1 -> 4 | AJ8: 0 | AL8: =AL7+1 -> 4 | AM8: 0
B9: =B8+1 -> 8 | C9: 6 | E9: =E8+1 -> 11 | F9: 34 | H9: 9 | I9: 3 | K9: =K8+1 -> 5 | L9: 0 | N9: =N8+1 -> 5 | O9: 2 | Q9: =Q8+1 -> 5 | R9: 0 | T9: =T8+1 -> 5 | U9: 2 | W9: =W8+1 -> 5 | X9: 0 | Z9: =Z8+1 -> 5 | AA9: 2 | AC9: =AC8+1 -> 5 | AD9: 0 | AF9: =AF8+1 -> 5 | AG9: 0 | AI9: =AI8+1 -> 5 | AJ9: 0 | AL9: =AL8+1 -> 5 | AM9: 2
B10: =B9+1 -> 9 | C10: 6 | E10: =E9+1 -> 12 | F10: 35 | H10: 10 | I10: 3 | K10: =K9+1 -> 6 | L10: 0 | N10: =N9+1 -> 6 | O10: 2 | Q10: =Q9+1 -> 6 | R10: 1 | T10: =T9+1 -> 6 | U10: 3 | W10: =W9+1 -> 6 | X10: 1 | Z10: =Z9+1 -> 6 | AA10: 3 | AC10: =AC9+1 -> 6 | AD10: 0 | AF10: =AF9+1 -> 6 | AG10: 1 | AI10: =AI9+1 -> 6 | AJ10: 0 | AL10: =AL9+1 -> 6 | AM10: 4
B11: =B10+1 -> 10 | C11: 6 | E11: =E10+1 -> 13 | F11: 36 | H11: 11 | I11: 4 | K11: =K10+1 -> 7 | L11: 0 | N11: =N10+1 -> 7 | O11: 3 | Q11: =Q10+1 -> 7 | R11: 1 | T11: =T10+1 -> 7 | U11: 4 | W11: =W10+1 -> 7 | X11: 2 | Z11: =Z10+1 -> 7 | AA11: 4 | AC11: =AC10+1 -> 7 | AD11: 0 | AF11: =AF10+1 -> 7 | AG11: 1 | AI11: =AI10+1 -> 7 | AJ11: 0 | AL11: =AL10+1 -> 7 | AM11: 5
B12: =B11+1 -> 11 | C12: 7 | E12: =E11+1 -> 14 | F12: 37 | H12: 12 | I12: 4 | K12: =K11+1 -> 8 | L12: 0 | N12: =N11+1 -> 8 | O12: 4 | Q12: =Q11+1 -> 8 | R12: 2 | T12: =T11+1 -> 8 | U12: 5 | W12: =W11+1 -> 8 | X12: 2 | Z12: =Z11+1 -> 8 | AA12: 4 | AC12: =AC11+1 -> 8 | AD12: 0 | AF12: =AF11+1 -> 8 | AG12: 2 | AI12: =AI11+1 -> 8 | AJ12: 0 | AL12: =AL11+1 -> 8 | AM12: 6
B13: =B12+1 -> 12 | C13: 7 | E13: =E12+1 -> 15 | F13: 40 | H13: 13 | I13: 5 | K13: =K12+1 -> 9 | L13: 0 | N13: =N12+1 -> 9 | O13: 9 | Q13: =Q12+1 -> 9 | R13: 3 | T13: =T12+1 -> 9 | U13: 5 | W13: =W12+1 -> 9 | X13: 3 | Z13: =Z12+1 -> 9 | AA13: 5 | AC13: =AC12+1 -> 9 | AD13: 0 | AF13: =AF12+1 -> 9 | AG13: 2 | AI13: =AI12+1 -> 9 | AJ13: 0 | AL13: =AL12+1 -> 9 | AM13: 7
B14: =B13+1 -> 13 | C14: 8 | E14: =E13+1 -> 16 | F14: 42 | H14: 14 | I14: 5 | K14: =K13+1 -> 10 | L14: 0 | N14: =N13+1 -> 10 | O14: 6 | Q14: =Q13+1 -> 10 | R14: 3 | T14: =T13+1 -> 10 | U14: 6 | W14: =W13+1 -> 10 | X14: 3 | Z14: =Z13+1 -> 10 | AA14: 5 | AC14: =AC13+1 -> 10 | AD14: 0 | AF14: =AF13+1 -> 10 | AG14: 3 | AI14: =AI13+1 -> 10 | AJ14: 0 | AL14: =AL13+1 -> 10 | AM14: 9
B15: =B14+1 -> 14 | C15: 8 | E15: =E14+1 -> 17 | F15: 43 | H15: 15 | I15: 6 | K15: =K14+1 -> 11 | L15: 0 | N15: =N14+1 -> 11 | O15: 7 | Q15: =Q14+1 -> 11 | R15: 4 | T15: =T14+1 -> 11 | U15: 7 | W15: =W14+1 -> 11 | X15: 3 | Z15: =Z14+1 -> 11 | AA15: 6 | AC15: =AC14+1 -> 11 | AD15: 0 | AF15: =AF14+1 -> 11 | AG15: 3 | AI15: =AI14+1 -> 11 | AJ15: 0 | AL15: =AL14+1 -> 11 | AM15: 11
B16: =B15+1 -> 15 | C16: 9 | E16: =E15+1 -> 18 | F16: 45 | H16: 16 | I16: 7 | K16: =K15+1 -> 12 | L16: 0 | N16: =N15+1 -> 12 | O16: 8 | Q16: =Q15+1 -> 12 | R16: 5 | T16: =T15+1 -> 12 | U16: 8 | W16: =W15+1 -> 12 | X16: 4 | Z16: =Z15+1 -> 12 | AA16: 6 | AC16: =AC15+1 -> 12 | AD16: 0 | AF16: =AF15+1 -> 12 | AG16: 4 | AI16: =AI15+1 -> 12 | AJ16: 24 | AL16: =AL15+1 -> 12 | AM16: 13
... B40: =B39+1 -> 39 | C40: 28 | E40: =E39+1 -> 42 | F40: 85 | H40: 40 | I40: 24 | K40: =K39+1 -> 36 | L40: 52 | N40: =N39+1 -> 36 | O40: 28 | Q40: =Q39+1 -> 36 | R40: 35 | T40: =T39+1 -> 36 | U40: 28 | W40: =W39+1 -> 36 | X40: 10 | Z40: =Z39+1 -> 36 | AA40: 36 | AC40: =AC39+1 -> 36 | AD40: 70 | AF40: =AF39+1 -> 36 | AG40: 28 | AI40: =AI39+1 -> 36 | AJ40: 58 | AL40: =AL39+1 -> 36 | AM40: 45
B41: =B40+1 -> 40 | C41: 29 | E41: =E40+1 -> 43 | F41: 88 | H41: 41 | I41: 25 | K41: =K40+1 -> 37 | L41: 54 | N41: =N40+1 -> 37 | O41: 29 | Q41: =Q40+1 -> 37 | R41: 36 | T41: =T40+1 -> 37 | U41: 29 | W41: =W40+1 -> 37 | X41: 11 | Z41: =Z40+1 -> 37 | AA41: 37 | AC41: =AC40+1 -> 37 | AD41: 71 | AF41: =AF40+1 -> 37 | AG41: 30 | AL41: =AL40+1 -> 37 | AM41: 46
B42: =B41+1 -> 41 | C42: 30 | E42: =E41+1 -> 44 | F42: 91 | H42: 42 | I42: 27 | K42: =K41+1 -> 38 | L42: 55 | N42: =N41+1 -> 38 | O42: 29 | Q42: =Q41+1 -> 38 | R42: 37 | T42: =T41+1 -> 38 | U42: 30 | W42: =W41+1 -> 38 | X42: 11 | Z42: =Z41+1 -> 38 | AA42: 40 | AC42: =AC41+1 -> 38 | AD42: 73 | AF42: =AF41+1 -> 38 | AG42: 31 | AL42: =AL41+1 -> 38 | AM42: 47
B43: =B42+1 -> 42 | C43: 31 | E43: =E42+1 -> 45 | F43: 95 | H43: 43 | I43: 28 | K43: =K42+1 -> 39 | L43: 58 | N43: =N42+1 -> 39 | O43: 30 | Q43: =Q42+1 -> 39 | R43: 37 | T43: =T42+1 -> 39 | U43: 31 | W43: =W42+1 -> 39 | X43: 11 | Z43: =Z42+1 -> 39 | AA43: 41 | AC43: =AC42+1 -> 39 | AD43: 76 | AF43: =AF42+1 -> 39 | AG43: 32 | AL43: =AL42+1 -> 39 | AM43: 48
B44: =B43+1 -> 43 | C44: 31 | E44: =E43+1 -> 46 | F44: 95 | H44: 44 | I44: 29 | K44: =K43+1 -> 40 | L44: 61 | N44: =N43+1 -> 40 | O44: 31 | Q44: =Q43+1 -> 40 | R44: 38 | T44: =T43+1 -> 40 | U44: 32 | W44: =W43+1 -> 40 | X44: 12 | Z44: =Z43+1 -> 40 | AA44: 42 | AC44: =AC43+1 -> 40 | AD44: 79 | AF44: =AF43+1 -> 40 | AG44: 34 | AL44: =AL43+1 -> 40 | AM44: 49
B45: =B44+1 -> 44 | C45: 32 | E45: =E44+1 -> 47 | F45: 95 | H45: 45 | I45: 30 | K45: =K44+1 -> 41 | L45: 64 | N45: =N44+1 -> 41 | O45: 31 | Q45: =Q44+1 -> 41 | R45: 40 | T45: =T44+1 -> 41 | U45: 33 | W45: =W44+1 -> 41 | X45: 12 | Z45: =Z44+1 -> 41 | AA45: 43 | AC45: =AC44+1 -> 41 | AD45: 82 | AF45: =AF44+1 -> 41 | AG45: 35 | AL45: =AL44+1 -> 41 | AM45: 49
B46: =B45+1 -> 45 | C46: 33 | E46: =E45+1 -> 48 | F46: 95 | H46: 46 | I46: 31 | K46: =K45+1 -> 42 | L46: 67 | N46: =N45+1 -> 42 | O46: 31 | Q46: =Q45+1 -> 42 | R46: 41 | T46: =T45+1 -> 42 | U46: 34 | W46: =W45+1 -> 42 | X46: 12 | Z46: =Z45+1 -> 42 | AA46: 44 | AC46: =AC45+1 -> 42 | AD46: 85 | AF46: =AF45+1 -> 42 | AG46: 36 | AL46: =AL45+1 -> 42 | AM46: 50
B47: =B46+1 -> 46 | C47: 34 | E47: =E46+1 -> 49 | F47: 95 | H47: 47 | I47: 34 | K47: =K46+1 -> 43 | L47: 71 | N47: =N46+1 -> 43 | O47: 32 | Q47: =Q46+1 -> 43 | R47: 42 | T47: =T46+1 -> 43 | U47: 34 | W47: =W46+1 -> 43 | X47: 13 | Z47: =Z46+1 -> 43 | AA47: 46 | AC47: =AC46+1 -> 43 | AD47: 91 | AF47: =AF46+1 -> 43 | AG47: 37 | AL47: =AL46+1 -> 43 | AM47: 51
B48: =B47+1 -> 47 | C48: 34 | E48: =E47+1 -> 50 | F48: 95 | H48: 48 | I48: 37 | K48: =K47+1 -> 44 | L48: 71 | N48: =N47+1 -> 44 | O48: 32 | Q48: =Q47+1 -> 44 | R48: 43 | T48: =T47+1 -> 44 | U48: 35 | W48: =W47+1 -> 44 | X48: 13 | Z48: =Z47+1 -> 44 | AA48: 47 | AC48: =AC47+1 -> 44 | AD48: 95 | AF48: =AF47+1 -> 44 | AG48: 40 | AL48: =AL47+1 -> 44 | AM48: 52
B49: =B48+1 -> 48 | C49: 35 | E49: =E48+1 -> 51 | F49: 95 | H49: 49 | I49: 40 | K49: =K48+1 -> 45 | L49: 71 | N49: =N48+1 -> 45 | O49: 33 | Q49: =Q48+1 -> 45 | R49: 43 | T49: =T48+1 -> 45 | U49: 36 | W49: =W48+1 -> 45 | X49: 13 | Z49: =Z48+1 -> 45 | AA49: 48 | AC49: =AC48+1 -> 45 | AD49: 95 | AF49: =AF48+1 -> 45 | AG49: 41 | AL49: =AL48+1 -> 45 | AM49: 52
B50: =B49+1 -> 49 | C50: 36 | E50: =E49+1 -> 52 | F50: 95 | H50: 50 | I50: 41 | K50: =K49+1 -> 46 | L50: 71 | N50: =N49+1 -> 46 | O50: 34 | Q50: =Q49+1 -> 46 | R50: 44 | T50: =T49+1 -> 46 | U50: 37 | W50: =W49+1 -> 46 | X50: 14 | Z50: =Z49+1 -> 46 | AA50: 49 | AC50: =AC49+1 -> 46 | AD50: 95 | AF50: =AF49+1 -> 46 | AG50: 43 | AL50: =AL49+1 -> 46 | AM50: 53
B51: =B50+1 -> 50 | C51: 37 | E51: =E50+1 -> 53 | F51: 95 | H51: 51 | I51: 43 | K51: =K50+1 -> 47 | L51: 71 | N51: =N50+1 -> 47 | O51: 34 | Q51: =Q50+1 -> 47 | R51: 45 | T51: =T50+1 -> 47 | U51: 38 | W51: =W50+1 -> 47 | X51: 14 | Z51: =Z50+1 -> 47 | AA51: 50 | AC51: =AC50+1 -> 47 | AD51: 95 | AF51: =AF50+1 -> 47 | AG51: 46 | AL51: =AL50+1 -> 47 | AM51: 54
B52: =B51+1 -> 51 | C52: 37 | E52: =E51+1 -> 54 | F52: 95 | H52: 52 | I52: 46 | K52: =K51+1 -> 48 | L52: 71 | N52: =N51+1 -> 48 | O52: 35 | Q52: =Q51+1 -> 48 | R52: 46 | T52: =T51+1 -> 48 | U52: 39 | W52: =W51+1 -> 48 | X52: 15 | Z52: =Z51+1 -> 48 | AA52: 52 | AC52: =AC51+1 -> 48 | AD52: 95 | AF52: =AF51+1 -> 48 | AG52: 47 | AL52: =AL51+1 -> 48 | AM52: 55
B53: =B52+1 -> 52 | C53: 38 | H53: 53 | I53: 49 | K53: =K52+1 -> 49 | L53: 71 | N53: =N52+1 -> 49 | O53: 35 | Q53: =Q52+1 -> 49 | R53: 47 | T53: =T52+1 -> 49 | U53: 40 | W53: =W52+1 -> 49 | X53: 15 | Z53: =Z52+1 -> 49 | AA53: 53 | AC53: =AC52+1 -> 49 | AD53: 95 | AF53: =AF52+1 -> 49 | AG53: 49
B54: =B53+1 -> 53 | C54: 40 | H54: 54 | I54: 55 | K54: =K53+1 -> 50 | L54: 71 | N54: =N53+1 -> 50 | O54: 36 | Q54: =Q53+1 -> 50 | R54: 48 | T54: =T53+1 -> 50 | U54: 42 | W54: =W53+1 -> 50 | X54: 16 | Z54: =Z53+1 -> 50 | AA54: 55 | AC54: =AC53+1 -> 50 | AD54: 95 | AF54: =AF53+1 -> 50 | AG54: 52
B55: =B54+1 -> 54 | C55: 41 | H55: 55 | I55: 61 | N55: =N54+1 -> 51 | O55: 37 | Q55: =Q54+1 -> 51 | R55: 49 | T55: =T54+1 -> 51 | U55: 43 | W55: =W54+1 -> 51 | X55: 16 | Z55: =Z54+1 -> 51 | AA55: 56 | AF55: =AF54+1 -> 51 | AG55: 55
B56: =B55+1 -> 55 | C56: 42 | H56: 56 | I56: 67 | N56: =N55+1 -> 52 | O56: 37 | Q56: =Q55+1 -> 52 | R56: 51 | T56: =T55+1 -> 52 | U56: 44 | W56: =W55+1 -> 52 | X56: 17 | Z56: =Z55+1 -> 52 | AA56: 58 | AF56: =AF55+1 -> 52 | AG56: 61
B57: =B56+1 -> 56 | C57: 43 | H57: 57 | I57: 71 | N57: =N56+1 -> 53 | O57: 39 | T57: =T56+1 -> 53 | U57: 45 | W57: =W56+1 -> 53 | X57: 18 | Z57: =Z56+1 -> 53 | AA57: 59 | AF57: =AF56+1 -> 53 | AG57: 64
B58: =B57+1 -> 57 | C58: 44 | H58: 58 | I58: 71 | N58: =N57+1 -> 54 | O58: 40 | T58: =T57+1 -> 54 | U58: 46 | W58: =W57+1 -> 54 | X58: 54 | Z58: =Z57+1 -> 54 | AA58: 61 | AF58: =AF57+1 -> 54 | AG58: 67
B59: =B58+1 -> 58 | C59: 46 | H59: 59 | I59: 71 | N59: =N58+1 -> 55 | O59: 41 | T59: 55 | U59: 47 | W59: =W58+1 -> 55 | X59: 21 | Z59: =Z58+1 -> 55 | AA59: 64 | AF59: =AF58+1 -> 55 | AG59: 71
B60: =B59+1 -> 59 | C60: 49 | H60: 60 | I60: 71 | N60: =N59+1 -> 56 | O60: 42 | T60: 56 | U60: 48 | W60: =W59+1 -> 56 | X60: 22 | Z60: =Z59+1 -> 56 | AA60: 67 | AF60: =AF59+1 -> 56 | AG60: 71
B61: =B60+1 -> 60 | C61: 52 | N61: =N60+1 -> 57 | O61: 43 | T61: 57 | U61: 49 | W61: =W60+1 -> 57 | X61: 23 | Z61: =Z60+1 -> 57 | AA61: 71 | AF61: =AF60+1 -> 57 | AG61: 71
B62: =B61+1 -> 61 | C62: 55 | N62: =N61+1 -> 58 | O62: 44 | T62: 58 | U62: 50 | W62: =W61+1 -> 58 | X62: 24 | Z62: =Z61+1 -> 58 | AA62: 71 | AF62: =AF61+1 -> 58 | AG62: 71
B63: =B62+1 -> 62 | C63: 61 | N63: =N62+1 -> 59 | O63: 45 | T63: 59 | U63: 51 | W63: =W62+1 -> 59 | X63: 25 | Z63: =Z62+1 -> 59 | AA63: 71 | AF63: =AF62+1 -> 59 | AG63: 71
B64: =B63+1 -> 63 | C64: 64 | N64: =N63+1 -> 60 | O64: 46 | T64: 60 | U64: 52 | W64: =W63+1 -> 60 | X64: 27 | Z64: =Z63+1 -> 60 | AA64: 71 | AF64: =AF63+1 -> 60 | AG64: 71
...

Sheet Scaled Scores
A1: Scaled Scores - Adaptive - Self-Care
D3: Self Care (SC) | H3: Personal Responsibility | L3: Adult Interaction | P3: Peer Interaction | T3: Self Concept - Social Role | X3: Receptive Communication | AB3: Expressive Communication | AF3: Gross Motor | AJ3: Fine Motor | AN3: Perceptiual Motor | AR3: Attention and Memory | AV3: Reasoning and Academic Skills | AZ3: Perception and Concepts
D4: Score | E4: Index | F4: Sscore | G4: Pct'tile | H4: Score | I4: Ind | J4: Sscore | K4: Pct'tile | L4: Score | M4: Index | N4: Sscore | O4: Pct'tile | P4: Score | Q4: Ind | R4: Sscore | S4: Pct'tile | T4: Score | U4: Ind | V4: Sscore | W4: Pct'tile | X4: Score | Y4: Ind | Z4: Sscore | AA4: Pct'tile | AB4: Score | AC4: Ind | AD4: Sscore | AE4: Pct'tile | AF4: Score | AG4: Ind | AH4: Sscore | AI4: Pct'tile | AJ4: Score | AK4: Ind | AL4: Sscore | AM4: Pct'tile | AN4: Score | AO4: Ind | AP4: Sscore | AQ4: Pct'tile | AR4: Score | AS4: Ind | AT4: Sscore | AU4: Pct'tile | AV4: Score | AW4: Ind | AX4: Sscore | AY4: Pct'tile | AZ4: Score | BA4: Ind | BB4: Sscore | BC4: Pct'tile
D5: =Summary!L8+0.01*Summary!D5 -> 36.25 | E5: 1 | F5: 2 | G5: <1 | H5: =Summary!L8+0.01*Summary!D6 -> 36.16 | I5: 24 | J5: 1 | K5: <1 | L5: =Summary!L8+0.01*Summary!D9 -> 36.16 | M5: 1 | N5: 2 | O5: <1 | P5: =Summary!L8+0.01*Summary!D10 -> 36.06 | Q5: 24 | R5: 1 | S5: <1 | T5: =Summary!L8+0.01*Summary!D11 -> 36 | U5: 1 | V5: 2 | W5: <1 | X5: =Summary!L8+0.01*Summary!D14 -> 36.1 | Y5: 1 | Z5: 2 | AA5: <1 | AB5: =Summary!L8+0.01*Summary!D15 -> 36.14 | AC5: 1 | AD5: 2 | AE5: <1 | AF5: =Summary!L8+0.01*Summary!D18 -> 36.3 | AG5: 1 | AH5: 2 | AI5: <1 | AJ5: =Summary!L8+0.01*Summary!D19 -> 36.28 | AK5: 1 | AL5: 2 | AM5: <1 | AN5: =Summary!L8+0.01*Summary!D20 -> 36.12 | AO5: 24 | AP5: 1 | AQ5: <1 | AR5: =Summary!L8+0.01*Summary!D23 -> 36.28 | AS5: 1 | AT5: 2 | AU5: <1 | AV5: =Summary!L8+0.01*Summary!D24 -> 36.16 | AW5: 24 | AX5: 1 | AY5: <1 | AZ5: =Summary!L8+0.01*Summary!D25 -> 36.1 | BA5: 1 | BB5: 2 | BC5: <1
E6: 1.01 | F6: 4 | G6: 2 | I6: 24.01 | J6: 3 | K6: 1 | M6: 1.01 | N6: 4 | O6: 2 | Q6: 24.01 | R6: 2 | S6: <1 | U6: 1.01 | V6: 4 | W6: 2 | Y6: 1.01 | Z6: 4 | AA6: 2 | AC6: 1.01 | AD6: 4 | AE6: 2 | AG6: 1.01 | AH6: 4 | AI6: 2 | AK6: 1.01 | AL6: 4 | AM6: 2 | AO6: 24.06 | AP6: 2 | AQ6: <1 | AS6: 1.01 | AT6: 4 | AU6: 2 | AW6: 24.02 | AX6: 2 | AY6: <1 | BA6: 1.01 | BB6: 4 | BC6: 2
E7: 1.02 | F7: 6 | G7: 9 | I7: 24.02 | J7: 4 | K7: 2 | M7: 1.02 | N7: 6 | O7: 9 | Q7: 24.02 | R7: 3 | S7: 1 | U7: 1.02 | V7: 6 | W7: 9 | Y7: 1.02 | Z7: 6 | AA7: 9 | AC7: 1.02 | AD7: 6 | AE7: 9 | AG7: 1.02 | AH7: 6 | AI7: 9 | AK7: 1.02 | AL7: 6 | AM7: 9 | AO7: 24.08 | AP7: 3 | AQ7: 1 | AS7: 1.02 | AT7: 6 | AU7: 9 | AW7: 24.03 | AX7: 3 | AY7: 1 | BA7: 1.02 | BB7: 6 | BC7: 9
E8: 1.03 | F8: 8 | G8: 25 | I8: 24.03 | J8: 5 | K8: 5 | M8: 1.03 | N8: 7 | O8: 16 | Q8: 24.03 | R8: 4 | S8: 2 | U8: 1.03 | V8: 8 | W8: 25 | Y8: 1.03 | Z8: 7 | AA8: 16 | AC8: 1.03 | AD8: 8 | AE8: 25 | AG8: 1.03 | AH8: 8 | AI8: 25 | AK8: 1.03 | AL8: 8 | AM8: 25 | AO8: 24.09 | AP8: 4 | AQ8: 2 | AS8: 1.03 | AT8: 7 | AU8: 16 | AW8: 24.04 | AX8: 4 | AY8: 2 | BA8: 1.03 | BB8: 8 | BC8: 25
E9: 1.04 | F9: 10 | G9: 50 | I9: 24.04 | J9: 6 | K9: 9 | M9: 1.04 | N9: 8 | O9: 25 | Q9: 24.04 | R9: 5 | S9: 5 | U9: 1.04 | V9: 10 | W9: 50 | Y9: 1.04 | Z9: 8 | AA9: 25 | AC9: 1.04 | AD9: 10 | AE9: 50 | AG9: 1.04 | AH9: 9 | AI9: 37 | AK9: 1.04 | AL9: 10 | AM9: 50 | AO9: 24.1 | AP9: 5 | AQ9: 5 | AS9: 1.04 | AT9: 8 | AU9: 25 | AW9: 24.05 | AX9: 5 | AY9: 5 | BA9: 1.04 | BB9: 10 | BC9: 50
E10: 1.05 | F10: 11 | G10: 63 | I10: 24.05 | J10: 7 | K10: 16 | M10: 1.05 | N10: 9 | O10: 37 | Q10: 24.06 | R10: 6 | S10: 9 | U10: 1.05 | V10: 11 | W10: 63 | Y10: 1.05 | Z10: 9 | AA10: 37 | AC10: 1.05 | AD10: 11 | AE10: 63 | AG10: 1.05 | AH10: 10 | AI10: 50 | AK10: 1.05 | AL10: 12 | AM10: 75 | AO10: 24.11 | AP10: 6 | AQ10: 9 | AS10: 1.05 | AT10: 9 | AU10: 37 | AW10: 24.06 | AX10: 6 | AY10: 9 | BA10: 1.05 | BB10: 11 | BC10: 63
E11: 1.06 | F11: 12 | G11: 75 | I11: 24.06 | J11: 8 | K11: 25 | M11: 1.06 | N11: 10 | O11: 50 | Q11: 24.08 | R11: 7 | S11: 16 | U11: 1.06 | V11: 12 | W11: 75 | Y11: 1.06 | Z11: 10 | AA11: 50 | AC11: 1.06 | AD11: 12 | AE11: 75 | AG11: 1.06 | AH11: 11 | AI11: 63 | AK11: 1.06 | AL11: 13 | AM11: 85 | AO11: 24.12 | AP11: 7 | AQ11: 16 | AS11: 1.06 | AT11: 10 | AU11: 50 | AW11: 24.07 | AX11: 7 | AY11: 16 | BA11: 1.06 | BB11: 12 | BC11: 75
